<sdf version='1.6'>
  <world name='default'>
    <plugin name='config' filename='libPlayers_Config.so'>
      <param1 model='player1'>VSS_Player/yellow1</param1>
      <param2 model='player2'>VSS_Player/blue2</param2>
    </plugin>
    <light name='sun' type='directional'>
      <cast_shadows>1</cast_shadows>
      <pose frame=''>0 0 10 0 -0 0</pose>
      <diffuse>0.8 0.8 0.8 1</diffuse>
      <specular>0.1 0.1 0.1 1</specular>
      <attenuation>
        <range>1000</range>
        <constant>0.9</constant>
        <linear>0.01</linear>
        <quadratic>0.001</quadratic>
      </attenuation>
      <direction>-0.5 0.5 -1</direction>
    </light>
    <model name='ground_plane'>
      <static>1</static>
      <link name='link'>
        <collision name='collision'>
          <geometry>
            <plane>
              <normal>0 0 1</normal>
              <size>100 100</size>
            </plane>
          </geometry>
          <surface>
            <friction>
              <ode>
                <mu>100</mu>
                <mu2>50</mu2>
              </ode>
              <torsional>
                <ode/>
              </torsional>
            </friction>
            <contact>
              <ode/>
            </contact>
            <bounce/>
          </surface>
          <max_contacts>10</max_contacts>
        </collision>
        <visual name='visual'>
          <cast_shadows>0</cast_shadows>
          <geometry>
            <plane>
              <normal>0 0 1</normal>
              <size>100 100</size>
            </plane>
          </geometry>
          <material>
            <script>
              <uri>file://media/materials/scripts/gazebo.material</uri>
              <name>Gazebo/Grey</name>
            </script>
          </material>
        </visual>
        <self_collide>0</self_collide>
        <kinematic>0</kinematic>
        <gravity>1</gravity>
      </link>
    </model>
    <model name='player1'>
      <link name='player::chassi'>
        <pose frame=''>-0.2 0 0.01 0 -0 0</pose>
        <inertial>
          <pose frame=''>0 0 0.035 0 -0 0</pose>
          <mass>0.3136</mass>
          <inertia>
            <ixx>0.000295307</ixx>
            <ixy>0</ixy>
            <ixz>0</ixz>
            <iyy>0.000295307</iyy>
            <iyz>0</iyz>
            <izz>0.000334507</izz>
          </inertia>
        </inertial>
        <collision name='chassi_kicker_collision'>
          <geometry>
            <polyline>
              <height>0.04</height>
              <point>0.04 0.04</point>
              <point>-0.04 0.04</point>
              <point>-0.04 -0.04</point>
              <point>0.04 -0.04</point>
              <point>0.04 -0.025</point>
              <point>0.0383616 -0.0219186</point>
              <point>0.0369421 -0.0187303</point>
              <point>0.0357484 -0.0154508</point>
              <point>0.0347865 -0.0120961</point>
              <point>0.0340609 -0.00868241</point>
              <point>0.0335752 -0.00522642</point>
              <point>0.0333317 -0.00174497</point>
              <point>0.0333317 0.00174497</point>
              <point>0.0335752 0.00522642</point>
              <point>0.0340609 0.00868241</point>
              <point>0.0347865 0.0120961</point>
              <point>0.0357484 0.0154508</point>
              <point>0.0369421 0.0187303</point>
              <point>0.0383616 0.0219186</point>
              <point>0.04 0.025</point>
            </polyline>
          </geometry>
          <max_contacts>10</max_contacts>
          <surface>
            <contact>
              <ode/>
            </contact>
            <bounce/>
            <friction>
              <torsional>
                <ode/>
              </torsional>
              <ode/>
            </friction>
          </surface>
        </collision>
        <collision name='chassi_body_collision'>
          <pose frame=''>0 0 0.055 0 -0 0</pose>
          <geometry>
            <box>
              <size>0.08 0.08 0.03</size>
            </box>
          </geometry>
          <max_contacts>10</max_contacts>
          <surface>
            <contact>
              <ode/>
            </contact>
            <bounce/>
            <friction>
              <torsional>
                <ode/>
              </torsional>
              <ode/>
            </friction>
          </surface>
        </collision>
        <visual name='chassi_kicker_visual'>
          <geometry>
            <polyline>
              <height>0.04</height>
              <point>0.04 0.04</point>
              <point>-0.04 0.04</point>
              <point>-0.04 -0.04</point>
              <point>0.04 -0.04</point>
              <point>0.04 -0.025</point>
              <point>0.0383616 -0.0219186</point>
              <point>0.0369421 -0.0187303</point>
              <point>0.0357484 -0.0154508</point>
              <point>0.0347865 -0.0120961</point>
              <point>0.0340609 -0.00868241</point>
              <point>0.0335752 -0.00522642</point>
              <point>0.0333317 -0.00174497</point>
              <point>0.0333317 0.00174497</point>
              <point>0.0335752 0.00522642</point>
              <point>0.0340609 0.00868241</point>
              <point>0.0347865 0.0120961</point>
              <point>0.0357484 0.0154508</point>
              <point>0.0369421 0.0187303</point>
              <point>0.0383616 0.0219186</point>
              <point>0.04 0.025</point>
            </polyline>
          </geometry>
          <material>
            <script>
              <uri>file://Scripts</uri>
              <name>VSS_Player/DarkGrey</name>
            </script>
          </material>
        </visual>
        <visual name='chassi_body_visual'>
          <pose frame=''>0 0 0.054999 0 -0 0</pose>
          <geometry>
            <box>
              <size>0.08 0.08 0.029997</size>
            </box>
          </geometry>
          <material>
            <script>
              <uri>file://Scripts</uri>
              <name>VSS_Player/DarkGrey</name>
            </script>
          </material>
        </visual>
        <visual name='chassi_tag_visual'>
          <pose frame=''>0 0 0.069997 0 -0 0</pose>
          <geometry>
            <box>
              <size>0.08 0.08 7e-06</size>
            </box>
          </geometry>
          <material>
            <script>
              <uri>file://Scripts</uri>
              <uri>file://Textures/VSS</uri>
              <name>__default__</name>
            </script>
          </material>
          <plugin name='texture' filename='libchange_texture.so'/>
        </visual>
        <self_collide>0</self_collide>
        <kinematic>0</kinematic>
        <gravity>1</gravity>
      </link>
      <link name='player::left_wheel'>
        <pose frame=''>-0.2155 0.033 0.016 1.5708 -0 0</pose>
        <inertial>
          <mass>0.00804248</mass>
          <inertia>
            <ixx>5.81739e-07</ixx>
            <ixy>0</ixy>
            <ixz>0</ixz>
            <iyy>5.81739e-07</iyy>
            <iyz>0</iyz>
            <izz>1.02944e-06</izz>
          </inertia>
        </inertial>
        <collision name='left_wheel_collision'>
          <geometry>
            <cylinder>
              <radius>0.016</radius>
              <length>0.01</length>
            </cylinder>
          </geometry>
          <surface>
            <friction>
              <ode>
                <mu>50</mu>
                <mu2>50</mu2>
              </ode>
              <torsional>
                <ode/>
              </torsional>
            </friction>
            <contact>
              <ode/>
            </contact>
            <bounce/>
          </surface>
          <max_contacts>10</max_contacts>
        </collision>
        <visual name='left_wheel_visual'>
          <geometry>
            <cylinder>
              <radius>0.016</radius>
              <length>0.01</length>
            </cylinder>
          </geometry>
          <material>
            <script>
              <uri>file://Scripts</uri>
              <name>VSS_Player/DarkGrey</name>
            </script>
          </material>
        </visual>
        <self_collide>0</self_collide>
        <kinematic>0</kinematic>
        <gravity>1</gravity>
      </link>
      <link name='player::right_wheel'>
        <pose frame=''>-0.2155 -0.033 0.016 1.5708 -0 0</pose>
        <inertial>
          <mass>0.00804248</mass>
          <inertia>
            <ixx>5.81739e-07</ixx>
            <ixy>0</ixy>
            <ixz>0</ixz>
            <iyy>5.81739e-07</iyy>
            <iyz>0</iyz>
            <izz>1.02944e-06</izz>
          </inertia>
        </inertial>
        <collision name='right_wheel_collision'>
          <geometry>
            <cylinder>
              <radius>0.016</radius>
              <length>0.01</length>
            </cylinder>
          </geometry>
          <surface>
            <friction>
              <ode>
                <mu>50</mu>
                <mu2>50</mu2>
              </ode>
              <torsional>
                <ode/>
              </torsional>
            </friction>
            <contact>
              <ode/>
            </contact>
            <bounce/>
          </surface>
          <max_contacts>10</max_contacts>
        </collision>
        <visual name='right_wheel_visual'>
          <geometry>
            <cylinder>
              <radius>0.016</radius>
              <length>0.01</length>
            </cylinder>
          </geometry>
          <material>
            <script>
              <uri>file://Scripts</uri>
              <name>VSS_Player/DarkGrey</name>
            </script>
          </material>
        </visual>
        <self_collide>0</self_collide>
        <kinematic>0</kinematic>
        <gravity>1</gravity>
      </link>
      <link name='player::ball_wheel'>
        <pose frame=''>-0.18 0 0.01 0 -0 0</pose>
        <inertial>
          <mass>0.00418879</mass>
          <inertia>
            <ixx>1.67552e-07</ixx>
            <ixy>0</ixy>
            <ixz>0</ixz>
            <iyy>1.67552e-07</iyy>
            <iyz>0</iyz>
            <izz>1.67552e-07</izz>
          </inertia>
        </inertial>
        <collision name='ball_wheel_collision'>
          <geometry>
            <sphere>
              <radius>0.01</radius>
            </sphere>
          </geometry>
          <surface>
            <friction>
              <ode>
                <mu>1</mu>
                <mu2>1</mu2>
              </ode>
              <torsional>
                <ode/>
              </torsional>
            </friction>
            <contact>
              <ode/>
            </contact>
            <bounce/>
          </surface>
          <max_contacts>10</max_contacts>
        </collision>
        <visual name='ball_wheel_visual'>
          <geometry>
            <sphere>
              <radius>0.01</radius>
            </sphere>
          </geometry>
          <material>
            <script>
              <uri>file://Scripts</uri>
              <name>VSS_Player/DarkGrey</name>
            </script>
          </material>
        </visual>
        <self_collide>0</self_collide>
        <kinematic>0</kinematic>
        <gravity>1</gravity>
      </link>
      <joint name='player::chassi_left_wheel' type='revolute'>
        <parent>player::chassi</parent>
        <child>player::left_wheel</child>
        <axis>
          <xyz>0 0 -1</xyz>
          <use_parent_model_frame>0</use_parent_model_frame>
          <limit>
            <lower>-1e+16</lower>
            <upper>1e+16</upper>
          </limit>
          <dynamics>
            <spring_reference>0</spring_reference>
            <spring_stiffness>0</spring_stiffness>
          </dynamics>
        </axis>
      </joint>
      <joint name='player::chassi_right_wheel' type='revolute'>
        <parent>player::chassi</parent>
        <child>player::right_wheel</child>
        <axis>
          <xyz>0 0 -1</xyz>
          <use_parent_model_frame>0</use_parent_model_frame>
          <limit>
            <lower>-1e+16</lower>
            <upper>1e+16</upper>
          </limit>
          <dynamics>
            <spring_reference>0</spring_reference>
            <spring_stiffness>0</spring_stiffness>
          </dynamics>
        </axis>
      </joint>
      <joint name='player::chassi_ball_wheel' type='ball'>
        <parent>player::chassi</parent>
        <child>player::ball_wheel</child>
      </joint>
      <plugin name='player 1 plugin' filename='libpid_control_plugin.so'>
        <velocity>true</velocity>
        <pid>0.001 0 0</pid>
      </plugin>
    </model>
    <model name='player2'>
      <link name='player::chassi'>
        <pose frame=''>0.2 0 0.01 0 -0 3.14</pose>
        <inertial>
          <pose frame=''>0 0 0.035 0 -0 0</pose>
          <mass>0.3136</mass>
          <inertia>
            <ixx>0.000295307</ixx>
            <ixy>0</ixy>
            <ixz>0</ixz>
            <iyy>0.000295307</iyy>
            <iyz>0</iyz>
            <izz>0.000334507</izz>
          </inertia>
        </inertial>
        <collision name='chassi_kicker_collision'>
          <geometry>
            <polyline>
              <height>0.04</height>
              <point>0.04 0.04</point>
              <point>-0.04 0.04</point>
              <point>-0.04 -0.04</point>
              <point>0.04 -0.04</point>
              <point>0.04 -0.025</point>
              <point>0.0383616 -0.0219186</point>
              <point>0.0369421 -0.0187303</point>
              <point>0.0357484 -0.0154508</point>
              <point>0.0347865 -0.0120961</point>
              <point>0.0340609 -0.00868241</point>
              <point>0.0335752 -0.00522642</point>
              <point>0.0333317 -0.00174497</point>
              <point>0.0333317 0.00174497</point>
              <point>0.0335752 0.00522642</point>
              <point>0.0340609 0.00868241</point>
              <point>0.0347865 0.0120961</point>
              <point>0.0357484 0.0154508</point>
              <point>0.0369421 0.0187303</point>
              <point>0.0383616 0.0219186</point>
              <point>0.04 0.025</point>
            </polyline>
          </geometry>
          <max_contacts>10</max_contacts>
          <surface>
            <contact>
              <ode/>
            </contact>
            <bounce/>
            <friction>
              <torsional>
                <ode/>
              </torsional>
              <ode/>
            </friction>
          </surface>
        </collision>
        <collision name='chassi_body_collision'>
          <pose frame=''>0 0 0.055 0 -0 0</pose>
          <geometry>
            <box>
              <size>0.08 0.08 0.03</size>
            </box>
          </geometry>
          <max_contacts>10</max_contacts>
          <surface>
            <contact>
              <ode/>
            </contact>
            <bounce/>
            <friction>
              <torsional>
                <ode/>
              </torsional>
              <ode/>
            </friction>
          </surface>
        </collision>
        <visual name='chassi_kicker_visual'>
          <geometry>
            <polyline>
              <height>0.04</height>
              <point>0.04 0.04</point>
              <point>-0.04 0.04</point>
              <point>-0.04 -0.04</point>
              <point>0.04 -0.04</point>
              <point>0.04 -0.025</point>
              <point>0.0383616 -0.0219186</point>
              <point>0.0369421 -0.0187303</point>
              <point>0.0357484 -0.0154508</point>
              <point>0.0347865 -0.0120961</point>
              <point>0.0340609 -0.00868241</point>
              <point>0.0335752 -0.00522642</point>
              <point>0.0333317 -0.00174497</point>
              <point>0.0333317 0.00174497</point>
              <point>0.0335752 0.00522642</point>
              <point>0.0340609 0.00868241</point>
              <point>0.0347865 0.0120961</point>
              <point>0.0357484 0.0154508</point>
              <point>0.0369421 0.0187303</point>
              <point>0.0383616 0.0219186</point>
              <point>0.04 0.025</point>
            </polyline>
          </geometry>
          <material>
            <script>
              <uri>file://Scripts</uri>
              <name>VSS_Player/DarkGrey</name>
            </script>
          </material>
        </visual>
        <visual name='chassi_body_visual'>
          <pose frame=''>0 0 0.054999 0 -0 0</pose>
          <geometry>
            <box>
              <size>0.08 0.08 0.029997</size>
            </box>
          </geometry>
          <material>
            <script>
              <uri>file://Scripts</uri>
              <name>VSS_Player/DarkGrey</name>
            </script>
          </material>
        </visual>
        <visual name='chassi_tag_visual'>
          <pose frame=''>0 0 0.069997 0 -0 0</pose>
          <geometry>
            <box>
              <size>0.08 0.08 7e-06</size>
            </box>
          </geometry>
          <material>
            <script>
              <uri>file://Scripts</uri>
              <uri>file://Textures/VSS</uri>
              <name>__default__</name>
            </script>
          </material>
          <plugin name='texture' filename='libchange_texture.so'/>
        </visual>
        <self_collide>0</self_collide>
        <kinematic>0</kinematic>
        <gravity>1</gravity>
      </link>
      <link name='player::left_wheel'>
        <pose frame=''>0.215447 -0.033025 0.016 1.5708 -0 3.14</pose>
        <inertial>
          <mass>0.00804248</mass>
          <inertia>
            <ixx>5.81739e-07</ixx>
            <ixy>0</ixy>
            <ixz>0</ixz>
            <iyy>5.81739e-07</iyy>
            <iyz>0</iyz>
            <izz>1.02944e-06</izz>
          </inertia>
        </inertial>
        <collision name='left_wheel_collision'>
          <geometry>
            <cylinder>
              <radius>0.016</radius>
              <length>0.01</length>
            </cylinder>
          </geometry>
          <surface>
            <friction>
              <ode>
                <mu>50</mu>
                <mu2>50</mu2>
              </ode>
              <torsional>
                <ode/>
              </torsional>
            </friction>
            <contact>
              <ode/>
            </contact>
            <bounce/>
          </surface>
          <max_contacts>10</max_contacts>
        </collision>
        <visual name='left_wheel_visual'>
          <geometry>
            <cylinder>
              <radius>0.016</radius>
              <length>0.01</length>
            </cylinder>
          </geometry>
          <material>
            <script>
              <uri>file://Scripts</uri>
              <name>VSS_Player/DarkGrey</name>
            </script>
          </material>
        </visual>
        <self_collide>0</self_collide>
        <kinematic>0</kinematic>
        <gravity>1</gravity>
      </link>
      <link name='player::right_wheel'>
        <pose frame=''>0.215553 0.032975 0.016 1.5708 -0 3.14</pose>
        <inertial>
          <mass>0.00804248</mass>
          <inertia>
            <ixx>5.81739e-07</ixx>
            <ixy>0</ixy>
            <ixz>0</ixz>
            <iyy>5.81739e-07</iyy>
            <iyz>0</iyz>
            <izz>1.02944e-06</izz>
          </inertia>
        </inertial>
        <collision name='right_wheel_collision'>
          <geometry>
            <cylinder>
              <radius>0.016</radius>
              <length>0.01</length>
            </cylinder>
          </geometry>
          <surface>
            <friction>
              <ode>
                <mu>50</mu>
                <mu2>50</mu2>
              </ode>
              <torsional>
                <ode/>
              </torsional>
            </friction>
            <contact>
              <ode/>
            </contact>
            <bounce/>
          </surface>
          <max_contacts>10</max_contacts>
        </collision>
        <visual name='right_wheel_visual'>
          <geometry>
            <cylinder>
              <radius>0.016</radius>
              <length>0.01</length>
            </cylinder>
          </geometry>
          <material>
            <script>
              <uri>file://Scripts</uri>
              <name>VSS_Player/DarkGrey</name>
            </script>
          </material>
        </visual>
        <self_collide>0</self_collide>
        <kinematic>0</kinematic>
        <gravity>1</gravity>
      </link>
      <link name='player::ball_wheel'>
        <pose frame=''>0.18 3.2e-05 0.01 0 -0 3.14</pose>
        <inertial>
          <mass>0.00418879</mass>
          <inertia>
            <ixx>1.67552e-07</ixx>
            <ixy>0</ixy>
            <ixz>0</ixz>
            <iyy>1.67552e-07</iyy>
            <iyz>0</iyz>
            <izz>1.67552e-07</izz>
          </inertia>
        </inertial>
        <collision name='ball_wheel_collision'>
          <geometry>
            <sphere>
              <radius>0.01</radius>
            </sphere>
          </geometry>
          <surface>
            <friction>
              <ode>
                <mu>1</mu>
                <mu2>1</mu2>
              </ode>
              <torsional>
                <ode/>
              </torsional>
            </friction>
            <contact>
              <ode/>
            </contact>
            <bounce/>
          </surface>
          <max_contacts>10</max_contacts>
        </collision>
        <visual name='ball_wheel_visual'>
          <geometry>
            <sphere>
              <radius>0.01</radius>
            </sphere>
          </geometry>
          <material>
            <script>
              <uri>file://Scripts</uri>
              <name>VSS_Player/DarkGrey</name>
            </script>
          </material>
        </visual>
        <self_collide>0</self_collide>
        <kinematic>0</kinematic>
        <gravity>1</gravity>
      </link>
      <joint name='player::chassi_left_wheel' type='revolute'>
        <parent>player::chassi</parent>
        <child>player::left_wheel</child>
        <axis>
          <xyz>0 0 -1</xyz>
          <use_parent_model_frame>0</use_parent_model_frame>
          <limit>
            <lower>-1e+16</lower>
            <upper>1e+16</upper>
          </limit>
          <dynamics>
            <spring_reference>0</spring_reference>
            <spring_stiffness>0</spring_stiffness>
          </dynamics>
        </axis>
      </joint>
      <joint name='player::chassi_right_wheel' type='revolute'>
        <parent>player::chassi</parent>
        <child>player::right_wheel</child>
        <axis>
          <xyz>0 0 -1</xyz>
          <use_parent_model_frame>0</use_parent_model_frame>
          <limit>
            <lower>-1e+16</lower>
            <upper>1e+16</upper>
          </limit>
          <dynamics>
            <spring_reference>0</spring_reference>
            <spring_stiffness>0</spring_stiffness>
          </dynamics>
        </axis>
      </joint>
      <joint name='player::chassi_ball_wheel' type='ball'>
        <parent>player::chassi</parent>
        <child>player::ball_wheel</child>
      </joint>
      <plugin name='player2 plugin' filename='libpid_control_plugin.so'>
        <velocity>true</velocity>
        <pid>0.001 0 0</pid>
      </plugin>
    </model>
    <model name='ball'>
      <link name='VSS ball::ball'>
        <pose frame=''>0 0 0.02135 0 -0 0</pose>
        <inertial>
          <mass>0.046</mass>
          <inertia>
            <ixx>8.38713e-06</ixx>
            <ixy>0</ixy>
            <ixz>0</ixz>
            <iyy>8.38713e-06</iyy>
            <iyz>0</iyz>
            <izz>8.38713e-06</izz>
          </inertia>
        </inertial>
        <collision name='ball_collision'>
          <geometry>
            <sphere>
              <radius>0.02135</radius>
            </sphere>
          </geometry>
          <surface>
            <friction>
              <ode>
                <mu>1</mu>
                <mu2>1</mu2>
              </ode>
              <torsional>
                <ode/>
              </torsional>
            </friction>
            <contact>
              <ode/>
            </contact>
            <bounce/>
          </surface>
          <max_contacts>10</max_contacts>
        </collision>
        <visual name='ball_visual'>
          <geometry>
            <sphere>
              <radius>0.02135</radius>
            </sphere>
          </geometry>
          <material>
            <ambient>1 0.5088 0.0468 1</ambient>
            <diffuse>1 0.5088 0.0468 1</diffuse>
            <specular>0.5 0.5 0.5 128</specular>
          </material>
        </visual>
        <self_collide>0</self_collide>
        <kinematic>0</kinematic>
        <gravity>1</gravity>
      </link>
    </model>
    <model name='camera'>
      <link name='camera::link'>
        <inertial>
          <mass>0.1</mass>
          <inertia>
            <ixx>0.000166667</ixx>
            <iyy>0.000166667</iyy>
            <izz>0.000166667</izz>
            <ixy>0</ixy>
            <ixz>0</ixz>
            <iyz>0</iyz>
          </inertia>
        </inertial>
        <collision name='collision'>
          <geometry>
            <box>
              <size>0.1 0.1 0.1</size>
            </box>
          </geometry>
          <max_contacts>10</max_contacts>
          <surface>
            <contact>
              <ode/>
            </contact>
            <bounce/>
            <friction>
              <torsional>
                <ode/>
              </torsional>
              <ode/>
            </friction>
          </surface>
        </collision>
        <visual name='visual'>
          <geometry>
            <box>
              <size>0.1 0.1 0.1</size>
            </box>
          </geometry>
        </visual>
        <sensor name='camera' type='camera'>
          <camera name='__default__'>
            <horizontal_fov>1.047</horizontal_fov>
            <image>
              <width>320</width>
              <height>240</height>
            </image>
            <clip>
              <near>0.1</near>
              <far>100</far>
            </clip>
          </camera>
          <always_on>1</always_on>
          <update_rate>30</update_rate>
          <visualize>1</visualize>
          <plugin name='camera_plugin' filename='libcamera_plugin.so'/>
        </sensor>
        <pose frame=''>0 0 2 0 1.57079 0</pose>
        <self_collide>0</self_collide>
        <kinematic>0</kinematic>
        <gravity>1</gravity>
      </link>
      <static>1</static>
    </model>
    <gravity>0 0 -9.8</gravity>
    <magnetic_field>6e-06 2.3e-05 -4.2e-05</magnetic_field>
    <atmosphere type='adiabatic'/>
    <physics name='default_physics' default='0' type='ode'>
      <max_step_size>0.001</max_step_size>
      <real_time_factor>1</real_time_factor>
      <real_time_update_rate>1000</real_time_update_rate>
    </physics>
    <scene>
      <ambient>0.4 0.4 0.4 1</ambient>
      <background>0.7 0.7 0.7 1</background>
      <shadows>1</shadows>
    </scene>
    <spherical_coordinates>
      <surface_model>EARTH_WGS84</surface_model>
      <latitude_deg>0</latitude_deg>
      <longitude_deg>0</longitude_deg>
      <elevation>0</elevation>
      <heading_deg>0</heading_deg>
    </spherical_coordinates>
    <state world_name='default'>
      <sim_time>0 0</sim_time>
      <real_time>0 0</real_time>
      <wall_time>1507916446 45997831</wall_time>
      <iterations>0</iterations>
      <model name='ball'>
        <pose frame=''>0 0 0.015 0 -0 0</pose>
        <scale>1 1 1</scale>
        <link name='VSS ball::ball'>
          <pose frame=''>0 0 0.03635 0 -0 0</pose>
          <velocity>0 0 0 0 -0 0</velocity>
          <acceleration>0 0 0 0 -0 0</acceleration>
          <wrench>0 0 0 0 -0 0</wrench>
        </link>
      </model>
      <model name='camera'>
        <pose frame=''>0 0 0 0 -0 0</pose>
        <scale>1 1 1</scale>
        <link name='camera::link'>
          <pose frame=''>0 0 2 0 1.57079 0</pose>
          <velocity>0 0 0 0 -0 0</velocity>
          <acceleration>0 0 0 0 -0 0</acceleration>
          <wrench>0 0 0 0 -0 0</wrench>
        </link>
      </model>
      <model name='campo_1'>
        <pose frame=''>0 0 0 0 -0 0</pose>
        <scale>1 1 1</scale>
        <link name='link_0'>
          <pose frame=''>0 0 0 0 -0 0</pose>
          <velocity>0 0 0 0 -0 0</velocity>
          <acceleration>0 0 0 0 -0 0</acceleration>
          <wrench>0 0 0 0 -0 0</wrench>
        </link>
      </model>
      <model name='ground_plane'>
        <pose frame=''>0 0 0 0 -0 0</pose>
        <scale>1 1 1</scale>
        <link name='link'>
          <pose frame=''>0 0 0 0 -0 0</pose>
          <velocity>0 0 0 0 -0 0</velocity>
          <acceleration>0 0 0 0 -0 0</acceleration>
          <wrench>0 0 0 0 -0 0</wrench>
        </link>
      </model>
      <model name='player1'>
        <pose frame=''>0 0 0.015 0 -0 0</pose>
        <scale>1 1 1</scale>
        <link name='player::ball_wheel'>
          <pose frame=''>-0.18 0 0.025 0 -0 0</pose>
          <velocity>0 0 0 0 -0 0</velocity>
          <acceleration>0 0 0 0 -0 0</acceleration>
          <wrench>0 0 0 0 -0 0</wrench>
        </link>
        <link name='player::chassi'>
          <pose frame=''>-0.2 0 0.025 0 -0 0</pose>
          <velocity>0 0 0 0 -0 0</velocity>
          <acceleration>0 0 0 0 -0 0</acceleration>
          <wrench>0 0 0 0 -0 0</wrench>
        </link>
        <link name='player::left_wheel'>
          <pose frame=''>-0.2155 0.033 0.031 1.5708 -0 0</pose>
          <velocity>0 0 0 0 -0 0</velocity>
          <acceleration>0 0 0 0 -0 0</acceleration>
          <wrench>0 0 0 0 -0 0</wrench>
        </link>
        <link name='player::right_wheel'>
          <pose frame=''>-0.2155 -0.033 0.031 1.5708 -0 0</pose>
          <velocity>0 0 0 0 -0 0</velocity>
          <acceleration>0 0 0 0 -0 0</acceleration>
          <wrench>0 0 0 0 -0 0</wrench>
        </link>
      </model>
      <model name='player2'>
        <pose frame=''>0 0 0.015 0 -0 0</pose>
        <scale>1 1 1</scale>
        <link name='player::ball_wheel'>
          <pose frame=''>0.18 3.2e-05 0.025 0 -0 3.14</pose>
          <velocity>0 0 0 0 -0 0</velocity>
          <acceleration>0 0 0 0 -0 0</acceleration>
          <wrench>0 0 0 0 -0 0</wrench>
        </link>
        <link name='player::chassi'>
          <pose frame=''>0.2 0 0.025 0 -0 3.14</pose>
          <velocity>0 0 0 0 -0 0</velocity>
          <acceleration>0 0 0 0 -0 0</acceleration>
          <wrench>0 0 0 0 -0 0</wrench>
        </link>
        <link name='player::left_wheel'>
          <pose frame=''>0.215447 -0.033025 0.031 1.5708 -0 3.14</pose>
          <velocity>0 0 0 0 -0 0</velocity>
          <acceleration>0 0 0 0 -0 0</acceleration>
          <wrench>0 0 0 0 -0 0</wrench>
        </link>
        <link name='player::right_wheel'>
          <pose frame=''>0.215553 0.032975 0.031 1.5708 -0 3.14</pose>
          <velocity>0 0 0 0 -0 0</velocity>
          <acceleration>0 0 0 0 -0 0</acceleration>
          <wrench>0 0 0 0 -0 0</wrench>
        </link>
      </model>
      <light name='sun'>
        <pose frame=''>0 0 10 0 -0 0</pose>
      </light>
    </state>
    <gui fullscreen='0'>
      <camera name='user_camera'>
        <pose frame=''>-1.31101 1.31668 0.818201 -0 0.443642 -0.927809</pose>
        <view_controller>orbit</view_controller>
        <projection_type>perspective</projection_type>
      </camera>
    </gui>
    <model name='campo_1'>
      <link name='link_0'>
        <pose frame=''>0 0 0 0 -0 0</pose>
        <inertial>
          <mass>1</mass>
          <inertia>
            <ixx>0.166667</ixx>
            <ixy>0</ixy>
            <ixz>0</ixz>
            <iyy>0.166667</iyy>
            <iyz>0</iyz>
            <izz>0.166667</izz>
          </inertia>
        </inertial>
        <visual name='visual'>
          <pose frame=''>0 0 0 0 -0 0</pose>
          <geometry>
            <mesh>
              <uri>/home/victor/catkin_ws/src/AutoGoal-UFMG/Gazebo-Simulation/Models/campo/campo.stl</uri>
              <scale>1 1 1</scale>
            </mesh>
          </geometry>
          <material>
            <lighting>1</lighting>
            <script>
              <uri>file://media/materials/scripts/gazebo.material</uri>
              <name>Gazebo/Grey</name>
            </script>
            <ambient>0.3 0.3 0.3 1</ambient>
            <diffuse>0.7 0.7 0.7 1</diffuse>
            <specular>0.01 0.01 0.01 1</specular>
            <emissive>0 0 0 1</emissive>
          </material>
          <cast_shadows>1</cast_shadows>
          <transparency>0</transparency>
        </visual>
        <collision name='collision'>
          <laser_retro>0</laser_retro>
          <max_contacts>10</max_contacts>
          <pose frame=''>0 0 0 0 -0 0</pose>
          <geometry>
            <mesh>
              <uri>/home/victor/catkin_ws/src/AutoGoal-UFMG/Gazebo-Simulation/Models/campo/campo.stl</uri>
              <scale>1 1 1</scale>
            </mesh>
          </geometry>
          <surface>
            <friction>
              <ode>
                <mu>1</mu>
                <mu2>1</mu2>
                <fdir1>0 0 0</fdir1>
                <slip1>0</slip1>
                <slip2>0</slip2>
              </ode>
              <torsional>
                <coefficient>1</coefficient>
                <patch_radius>0</patch_radius>
                <surface_radius>0</surface_radius>
                <use_patch_radius>1</use_patch_radius>
                <ode>
                  <slip>0</slip>
                </ode>
              </torsional>
            </friction>
            <bounce>
              <restitution_coefficient>0</restitution_coefficient>
              <threshold>1e+06</threshold>
            </bounce>
            <contact>
              <collide_without_contact>0</collide_without_contact>
              <collide_without_contact_bitmask>1</collide_without_contact_bitmask>
              <collide_bitmask>1</collide_bitmask>
              <ode>
                <soft_cfm>0</soft_cfm>
                <soft_erp>0.2</soft_erp>
                <kp>1e+13</kp>
                <kd>1</kd>
                <max_vel>0.01</max_vel>
                <min_depth>0</min_depth>
              </ode>
              <bullet>
                <split_impulse>1</split_impulse>
                <split_impulse_penetration_threshold>-0.01</split_impulse_penetration_threshold>
                <soft_cfm>0</soft_cfm>
                <soft_erp>0.2</soft_erp>
                <kp>1e+13</kp>
                <kd>1</kd>
              </bullet>
            </contact>
          </surface>
        </collision>
        <self_collide>0</self_collide>
        <kinematic>0</kinematic>
        <gravity>1</gravity>
      </link>
      <static>1</static>
      <allow_auto_disable>1</allow_auto_disable>
      <pose frame=''>0.034982 0.084834 0 0 -0 0</pose>
    </model>
  </world>
</sdf>
