<sdf version='1.6'>
  <world name='default'>
    <light name='sun' type='directional'>
      <cast_shadows>1</cast_shadows>
      <pose frame=''>0 0 10 0 -0 0</pose>
      <diffuse>0.8 0.8 0.8 1</diffuse>
      <specular>0.1 0.1 0.1 1</specular>
      <attenuation>
        <range>1000</range>
        <constant>0.9</constant>
        <linear>0.01</linear>
        <quadratic>0.001</quadratic>
      </attenuation>
      <direction>-0.5 0.5 -1</direction>
    </light>
    <model name='ground_plane'>
      <static>1</static>
      <link name='link'>
        <collision name='collision'>
          <geometry>
            <plane>
              <normal>0 0 1</normal>
              <size>100 100</size>
            </plane>
          </geometry>
          <surface>
            <friction>
              <ode>
                <mu>100</mu>
                <mu2>50</mu2>
              </ode>
              <torsional>
                <ode/>
              </torsional>
            </friction>
            <contact>
              <ode/>
            </contact>
            <bounce/>
          </surface>
          <max_contacts>10</max_contacts>
        </collision>
        <visual name='visual'>
          <cast_shadows>0</cast_shadows>
          <geometry>
            <plane>
              <normal>0 0 1</normal>
              <size>100 100</size>
            </plane>
          </geometry>
          <material>
            <script>
              <uri>file://media/materials/scripts/gazebo.material</uri>
              <name>Gazebo/Grey</name>
            </script>
          </material>
        </visual>
        <self_collide>0</self_collide>
        <kinematic>0</kinematic>
        <gravity>1</gravity>
      </link>
    </model>
    <model name='player'>
      <link name='player::chassi'>
        <pose frame=''>0 0 0.01 0 -0 0</pose>
        <inertial>
          <pose frame=''>0 0 0.035 0 -0 0</pose>
          <mass>0.3136</mass>
          <inertia>
            <ixx>0.000295307</ixx>
            <ixy>0</ixy>
            <ixz>0</ixz>
            <iyy>0.000295307</iyy>
            <iyz>0</iyz>
            <izz>0.000334507</izz>
          </inertia>
        </inertial>
        <collision name='chassi_collision'>
          <pose frame=''>0 0 0.035 0 -0 0</pose>
          <geometry>
            <box>
              <size>0.08 0.08 0.07</size>
            </box>
          </geometry>
          <max_contacts>10</max_contacts>
          <surface>
            <contact>
              <ode/>
            </contact>
            <bounce/>
            <friction>
              <torsional>
                <ode/>
              </torsional>
              <ode/>
            </friction>
          </surface>
        </collision>
        <visual name='chassi_body_visual'>
          <pose frame=''>0 0 0.034825 0 -0 0</pose>
          <geometry>
            <box>
              <size>0.08 0.08 0.06965</size>
            </box>
          </geometry>
        </visual>
        <visual name='chassi_tag_visual'>
          <pose frame=''>0 0 0.069825 0 -0 0</pose>
          <geometry>
            <box>
              <size>0.08 0.08 0.00035</size>
            </box>
          </geometry>
          <material>
            <script>
              <uri>file://Scripts</uri>
              <uri>file://Textures</uri>
              <name>VSS_Player/tag</name>
            </script>
          </material>
        </visual>
        <self_collide>0</self_collide>
        <kinematic>0</kinematic>
        <gravity>1</gravity>
      </link>
      <link name='player::left_wheel'>
        <pose frame=''>-0.0155 0.033 0.016 1.5708 -0 0</pose>
        <inertial>
          <mass>0.00402124</mass>
          <inertia>
            <ixx>2.9087e-07</ixx>
            <ixy>0</ixy>
            <ixz>0</ixz>
            <iyy>2.9087e-07</iyy>
            <iyz>0</iyz>
            <izz>5.14718e-07</izz>
          </inertia>
        </inertial>
        <collision name='left_wheel_collision'>
          <geometry>
            <cylinder>
              <radius>0.016</radius>
              <length>0.01</length>
            </cylinder>
          </geometry>
          <surface>
            <friction>
              <ode>
                <mu>50</mu>
                <mu2>50</mu2>
              </ode>
              <torsional>
                <ode/>
              </torsional>
            </friction>
            <contact>
              <ode/>
            </contact>
            <bounce/>
          </surface>
          <max_contacts>10</max_contacts>
        </collision>
        <visual name='left_wheel_visual'>
          <geometry>
            <cylinder>
              <radius>0.016</radius>
              <length>0.01</length>
            </cylinder>
          </geometry>
        </visual>
        <self_collide>0</self_collide>
        <kinematic>0</kinematic>
        <gravity>1</gravity>
      </link>
      <link name='player::right_wheel'>
        <pose frame=''>-0.0155 -0.033 0.016 1.5708 -0 0</pose>
        <inertial>
          <mass>0.00402124</mass>
          <inertia>
            <ixx>2.9087e-07</ixx>
            <ixy>0</ixy>
            <ixz>0</ixz>
            <iyy>2.9087e-07</iyy>
            <iyz>0</iyz>
            <izz>5.14718e-07</izz>
          </inertia>
        </inertial>
        <collision name='right_wheel_collision'>
          <geometry>
            <cylinder>
              <radius>0.016</radius>
              <length>0.01</length>
            </cylinder>
          </geometry>
          <surface>
            <friction>
              <ode>
                <mu>50</mu>
                <mu2>50</mu2>
              </ode>
              <torsional>
                <ode/>
              </torsional>
            </friction>
            <contact>
              <ode/>
            </contact>
            <bounce/>
          </surface>
          <max_contacts>10</max_contacts>
        </collision>
        <visual name='right_wheel_visual'>
          <geometry>
            <cylinder>
              <radius>0.016</radius>
              <length>0.01</length>
            </cylinder>
          </geometry>
        </visual>
        <self_collide>0</self_collide>
        <kinematic>0</kinematic>
        <gravity>1</gravity>
      </link>
      <link name='player::ball_wheel'>
        <pose frame=''>0.02 0 0.01 0 -0 0</pose>
        <inertial>
          <mass>0.00209439</mass>
          <inertia>
            <ixx>8.37758e-08</ixx>
            <ixy>0</ixy>
            <ixz>0</ixz>
            <iyy>8.37758e-08</iyy>
            <iyz>0</iyz>
            <izz>8.37758e-08</izz>
          </inertia>
        </inertial>
        <collision name='ball_wheel_collision'>
          <geometry>
            <sphere>
              <radius>0.01</radius>
            </sphere>
          </geometry>
          <surface>
            <friction>
              <ode>
                <mu>1</mu>
                <mu2>1</mu2>
              </ode>
              <torsional>
                <ode/>
              </torsional>
            </friction>
            <contact>
              <ode/>
            </contact>
            <bounce/>
          </surface>
          <max_contacts>10</max_contacts>
        </collision>
        <visual name='ball_wheel_visual'>
          <geometry>
            <sphere>
              <radius>0.01</radius>
            </sphere>
          </geometry>
        </visual>
        <self_collide>0</self_collide>
        <kinematic>0</kinematic>
        <gravity>1</gravity>
      </link>
      <joint name='player::chassi_left_wheel' type='revolute'>
        <parent>player::chassi</parent>
        <child>player::left_wheel</child>
        <axis>
          <xyz>0 0 -1</xyz>
          <use_parent_model_frame>0</use_parent_model_frame>
          <limit>
            <lower>-1e+16</lower>
            <upper>1e+16</upper>
          </limit>
          <dynamics>
            <spring_reference>0</spring_reference>
            <spring_stiffness>0</spring_stiffness>
          </dynamics>
        </axis>
      </joint>
      <joint name='player::chassi_right_wheel' type='revolute'>
        <parent>player::chassi</parent>
        <child>player::right_wheel</child>
        <axis>
          <xyz>0 0 -1</xyz>
          <use_parent_model_frame>0</use_parent_model_frame>
          <limit>
            <lower>-1e+16</lower>
            <upper>1e+16</upper>
          </limit>
          <dynamics>
            <spring_reference>0</spring_reference>
            <spring_stiffness>0</spring_stiffness>
          </dynamics>
        </axis>
      </joint>
      <joint name='player::chassi_ball_wheel' type='ball'>
        <parent>player::chassi</parent>
        <child>player::ball_wheel</child>
      </joint>
      <plugin name='player plugin' filename='libpid_control_plugin.so'>
        <velocity>true</velocity>
        <pid>0.001 0 0</pid>
      </plugin>
    </model>
    <model name='camera'>
      <link name='camera::link'>
        <inertial>
          <mass>0.1</mass>
          <inertia>
            <ixx>0.000166667</ixx>
            <iyy>0.000166667</iyy>
            <izz>0.000166667</izz>
            <ixy>0</ixy>
            <ixz>0</ixz>
            <iyz>0</iyz>
          </inertia>
        </inertial>
        <collision name='collision'>
          <geometry>
            <box>
              <size>0.1 0.1 0.1</size>
            </box>
          </geometry>
          <max_contacts>10</max_contacts>
          <surface>
            <contact>
              <ode/>
            </contact>
            <bounce/>
            <friction>
              <torsional>
                <ode/>
              </torsional>
              <ode/>
            </friction>
          </surface>
        </collision>
        <visual name='visual'>
          <geometry>
            <box>
              <size>0.1 0.1 0.1</size>
            </box>
          </geometry>
        </visual>
        <sensor name='camera' type='camera'>
          <camera name='__default__'>
            <horizontal_fov>1.047</horizontal_fov>
            <image>
              <width>320</width>
              <height>240</height>
            </image>
            <clip>
              <near>0.1</near>
              <far>100</far>
            </clip>
          </camera>
          <always_on>1</always_on>
          <update_rate>30</update_rate>
          <visualize>1</visualize>
          <plugin name='camera_plugin' filename='libcamera_plugin.so'/>
        </sensor>
        <pose frame=''>0 0 2 0 1.57079 0</pose>
        <self_collide>0</self_collide>
        <kinematic>0</kinematic>
        <gravity>1</gravity>
      </link>
      <static>1</static>
    </model>
    <gravity>0 0 -9.8</gravity>
    <magnetic_field>6e-06 2.3e-05 -4.2e-05</magnetic_field>
    <atmosphere type='adiabatic'/>
    <physics name='default_physics' default='0' type='ode'>
      <max_step_size>0.001</max_step_size>
      <real_time_factor>1</real_time_factor>
      <real_time_update_rate>1000</real_time_update_rate>
    </physics>
    <scene>
      <ambient>0.4 0.4 0.4 1</ambient>
      <background>0.7 0.7 0.7 1</background>
      <shadows>1</shadows>
    </scene>
    <spherical_coordinates>
      <surface_model>EARTH_WGS84</surface_model>
      <latitude_deg>0</latitude_deg>
      <longitude_deg>0</longitude_deg>
      <elevation>0</elevation>
      <heading_deg>0</heading_deg>
    </spherical_coordinates>
    <model name='campo'>
      <link name='link_0'>
        <pose frame=''>0 0 0 0 -0 0</pose>
        <inertial>
          <mass>1</mass>
          <inertia>
            <ixx>0.166667</ixx>
            <ixy>0</ixy>
            <ixz>0</ixz>
            <iyy>0.166667</iyy>
            <iyz>0</iyz>
            <izz>0.166667</izz>
          </inertia>
        </inertial>
        <visual name='visual'>
          <pose frame=''>0 0 0 0 -0 0</pose>
          <geometry>
            <mesh>
              <uri>/home/victor/catkin_ws/src/AutoGoal-UFMG/campo.stl</uri>
              <scale>1 1 1</scale>
            </mesh>
          </geometry>
          <material>
            <lighting>1</lighting>
            <script>
              <uri>file://media/materials/scripts/gazebo.material</uri>
              <name>Gazebo/Grey</name>
            </script>
            <ambient>0.3 0.3 0.3 1</ambient>
            <diffuse>0.7 0.7 0.7 1</diffuse>
            <specular>0.01 0.01 0.01 1</specular>
            <emissive>0 0 0 1</emissive>
          </material>
          <cast_shadows>1</cast_shadows>
          <transparency>0</transparency>
        </visual>
        <collision name='collision'>
          <laser_retro>0</laser_retro>
          <max_contacts>10</max_contacts>
          <pose frame=''>0 0 0 0 -0 0</pose>
          <geometry>
            <mesh>
              <uri>/home/victor/catkin_ws/src/AutoGoal-UFMG/campo.stl</uri>
              <scale>1 1 1</scale>
            </mesh>
          </geometry>
          <surface>
            <friction>
              <ode>
                <mu>1</mu>
                <mu2>1</mu2>
                <fdir1>0 0 0</fdir1>
                <slip1>0</slip1>
                <slip2>0</slip2>
              </ode>
              <torsional>
                <coefficient>1</coefficient>
                <patch_radius>0</patch_radius>
                <surface_radius>0</surface_radius>
                <use_patch_radius>1</use_patch_radius>
                <ode>
                  <slip>0</slip>
                </ode>
              </torsional>
            </friction>
            <bounce>
              <restitution_coefficient>0</restitution_coefficient>
              <threshold>1e+06</threshold>
            </bounce>
            <contact>
              <collide_without_contact>0</collide_without_contact>
              <collide_without_contact_bitmask>1</collide_without_contact_bitmask>
              <collide_bitmask>1</collide_bitmask>
              <ode>
                <soft_cfm>0</soft_cfm>
                <soft_erp>0.2</soft_erp>
                <kp>1e+13</kp>
                <kd>1</kd>
                <max_vel>0.01</max_vel>
                <min_depth>0</min_depth>
              </ode>
              <bullet>
                <split_impulse>1</split_impulse>
                <split_impulse_penetration_threshold>-0.01</split_impulse_penetration_threshold>
                <soft_cfm>0</soft_cfm>
                <soft_erp>0.2</soft_erp>
                <kp>1e+13</kp>
                <kd>1</kd>
              </bullet>
            </contact>
          </surface>
        </collision>
        <self_collide>0</self_collide>
        <kinematic>0</kinematic>
        <gravity>1</gravity>
      </link>
      <static>1</static>
      <allow_auto_disable>1</allow_auto_disable>
      <pose frame=''>0 0 0 0 -0 0</pose>
    </model>
    <state world_name='default'>
      <sim_time>10 283000000</sim_time>
      <real_time>10 342602023</real_time>
      <wall_time>1507868540 650730197</wall_time>
      <iterations>10283</iterations>
      <model name='camera'>
        <pose frame=''>0 0 0 0 -0 0</pose>
        <scale>1 1 1</scale>
        <link name='camera::link'>
          <pose frame=''>0 0 2 0 1.57079 0</pose>
          <velocity>0 0 0 0 -0 0</velocity>
          <acceleration>0 0 0 0 -0 0</acceleration>
          <wrench>0 0 0 0 -0 0</wrench>
        </link>
      </model>
      <model name='campo'>
        <pose frame=''>0 0 0 0 -0 0</pose>
        <scale>1 1 1</scale>
        <link name='link_0'>
          <pose frame=''>0 0 0 0 -0 0</pose>
          <velocity>0 0 0 0 -0 0</velocity>
          <acceleration>0 0 0 0 -0 0</acceleration>
          <wrench>0 0 0 0 -0 0</wrench>
        </link>
      </model>
      <model name='ground_plane'>
        <pose frame=''>0 0 0 0 -0 0</pose>
        <scale>1 1 1</scale>
        <link name='link'>
          <pose frame=''>0 0 0 0 -0 0</pose>
          <velocity>0 0 0 0 -0 0</velocity>
          <acceleration>0 0 0 0 -0 0</acceleration>
          <wrench>0 0 0 0 -0 0</wrench>
        </link>
      </model>
      <model name='player'>
        <pose frame=''>0.516807 0.142278 0.015472 7.7e-05 0.000857 -0.078464</pose>
        <scale>1 1 1</scale>
        <link name='player::ball_wheel'>
          <pose frame=''>0.536754 0.140709 0.025481 0.343926 0.689458 2.68453</pose>
          <velocity>0.082934 -0.00314 -0.010065 -2.80463 1.087 3.14158</velocity>
          <acceleration>-0.382088 0.227076 -21.4433 0 -0 0</acceleration>
          <wrench>-0.0008 0.000476 -0.044911 0 -0 0</wrench>
        </link>
        <link name='player::chassi'>
          <pose frame=''>0.516816 0.142277 0.025472 7.7e-05 0.000857 -0.078464</pose>
          <velocity>0.082855 -0.003117 -0.003338 0.098987 0.000875 -0.00134</velocity>
          <acceleration>-0.026726 -0.555295 -8.60682 2.26866 0.868148 -1.73798</acceleration>
          <wrench>-0.008381 -0.174141 -2.6991 0 -0 0</wrench>
        </link>
        <link name='player::left_wheel'>
          <pose frame=''>0.503955 0.176386 0.031489 -1.56894 1.31238 3.06493</pose>
          <velocity>0.082875 -0.004668 0.000363 0.295537 -1.10296 -0.00448</velocity>
          <acceleration>-0.6619 0.034148 -7.70772 -0.190794 1.13764 -2.02962</acceleration>
          <wrench>-0.002662 0.000137 -0.030995 0 -0 0</wrench>
        </link>
        <link name='player::right_wheel'>
          <pose frame=''>0.498782 0.110593 0.031483 -1.57099 0.079101 3.06311</pose>
          <velocity>0.082824 -0.003853 -0.006627 0.476461 -1.12172 0.001215</velocity>
          <acceleration>-0.050265 0.896911 -7.82805 0.648464 -1.32141 -2.75538</acceleration>
          <wrench>-0.000202 0.003607 -0.031478 0 -0 0</wrench>
        </link>
      </model>
      <light name='sun'>
        <pose frame=''>0 0 10 0 -0 0</pose>
      </light>
    </state>
    <gui fullscreen='0'>
      <camera name='user_camera'>
        <pose frame=''>1.20419 -1.19287 0.870122 0 0.491644 2.2722</pose>
        <view_controller>orbit</view_controller>
        <projection_type>perspective</projection_type>
      </camera>
    </gui>
  </world>
</sdf>
